Workbook

Sheet Summary_Tables
A1: Loans by Status (Count & Total Loan Amount)
A2: LoanStatus | B2: Count | C2: Total Loan Amount
A3: Active | B3: =COUNTIF(Loan_Data!$H$2:$H$601,"Active") -> 325 | C3: =SUMIF(Loan_Data!$H$2:$H$601,"Active",Loan_Data!$D$2:$D$601) -> 621868432
A4: Closed | B4: =COUNTIF(Loan_Data!$H$2:$H$601,"Closed") -> 183 | C4: =SUMIF(Loan_Data!$H$2:$H$601,"Closed",Loan_Data!$D$2:$D$601) -> 357081564
A5: Default | B5: =COUNTIF(Loan_Data!$H$2:$H$601,"Default") -> 26 | C5: =SUMIF(Loan_Data!$H$2:$H$601,"Default",Loan_Data!$D$2:$D$601) -> 52683519
A6: NPA | B6: =COUNTIF(Loan_Data!$H$2:$H$601,"NPA") -> 66 | C6: =SUMIF(Loan_Data!$H$2:$H$601,"NPA",Loan_Data!$D$2:$D$601) -> 115164473
A9: Loans by Type (Total Amount)
A10: LoanType | B10: Total Loan Amount
A11: Auto Loan | B11: =SUMIF(Loan_Data!$C$2:$C$601,"Auto Loan",Loan_Data!$D$2:$D$601) -> 67147978
A12: Business Loan | B12: =SUMIF(Loan_Data!$C$2:$C$601,"Business Loan",Loan_Data!$D$2:$D$601) -> 252361965
A13: Education Loan | B13: =SUMIF(Loan_Data!$C$2:$C$601,"Education Loan",Loan_Data!$D$2:$D$601) -> 125694348
A14: Gold Loan | B14: =SUMIF(Loan_Data!$C$2:$C$601,"Gold Loan",Loan_Data!$D$2:$D$601) -> 28138418
A15: Home Loan | B15: =SUMIF(Loan_Data!$C$2:$C$601,"Home Loan",Loan_Data!$D$2:$D$601) -> 630356049
A16: Personal Loan | B16: =SUMIF(Loan_Data!$C$2:$C$601,"Personal Loan",Loan_Data!$D$2:$D$601) -> 43099230
A19: KYC Status Breakdown
A20: KYCStatus | B20: Count
A21: Pending | B21: =COUNTIF(KYC_Data!$E$2:$E$946,"Pending") -> 139
A22: Rejected | B22: =COUNTIF(KYC_Data!$E$2:$E$946,"Rejected") -> 63
A23: Verified | B23: =COUNTIF(KYC_Data!$E$2:$E$946,"Verified") -> 743
A26: Credit Cards by Type (Count & Total Limit)
A27: CardType | B27: Count | C27: Total Limit
A28: Business | B28: =COUNTIF(Creditcard_Data!$C$2:$C$501,"Business") -> 106 | C28: =SUMIF(Creditcard_Data!$C$2:$C$501,"Business",Creditcard_Data!$D$2:$D$501) -> 84800000
A29: Classic | B29: =COUNTIF(Creditcard_Data!$C$2:$C$501,"Classic") -> 91 | C29: =SUMIF(Creditcard_Data!$C$2:$C$501,"Classic",Creditcard_Data!$D$2:$D$501) -> 6825000
A30: Gold | B30: =COUNTIF(Creditcard_Data!$C$2:$C$501,"Gold") -> 104 | C30: =SUMIF(Creditcard_Data!$C$2:$C$501,"Gold",Creditcard_Data!$D$2:$D$501) -> 15600000
A31: Platinum | B31: =COUNTIF(Creditcard_Data!$C$2:$C$501,"Platinum") -> 95 | C31: =SUMIF(Creditcard_Data!$C$2:$C$501,"Platinum",Creditcard_Data!$D$2:$D$501) -> 28500000
A32: Signature | B32: =COUNTIF(Creditcard_Data!$C$2:$C$501,"Signature") -> 104 | C32: =SUMIF(Creditcard_Data!$C$2:$C$501,"Signature",Creditcard_Data!$D$2:$D$501) -> 52000000
A35: Credit Card Status Breakdown
A36: CardStatus | B36: Count
A37: Active | B37: =COUNTIF(Creditcard_Data!$G$2:$G$501,"Active") -> 391
A38: Blocked | B38: =COUNTIF(Creditcard_Data!$G$2:$G$501,"Blocked") -> 54
A39: Closed | B39: =COUNTIF(Creditcard_Data!$G$2:$G$501,"Closed") -> 55
A42: Customers by Region
A43: Region | B43: Customer Count
A44: Central | B44: {=SUMPRODUCT((COUNTIFS(Branches_Data!$A$2:$A$31,Customer_Data!$U$2:$U$1051,Branches_Data!$E$2:$E$31,"Central")>0)*1)} -> 55
A45: East | B45: {=SUMPRODUCT((COUNTIFS(Branches_Data!$A$2:$A$31,Customer_Data!$U$2:$U$1051,Branches_Data!$E$2:$E$31,"East")>0)*1)} -> 180
A46: North | B46: {=SUMPRODUCT((COUNTIFS(Branches_Data!$A$2:$A$31,Customer_Data!$U$2:$U$1051,Branches_Data!$E$2:$E$31,"North")>0)*1)} -> 269
A47: South | B47: {=SUMPRODUCT((COUNTIFS(Branches_Data!$A$2:$A$31,Customer_Data!$U$2:$U$1051,Branches_Data!$E$2:$E$31,"South")>0)*1)} -> 309
A48: West | B48: {=SUMPRODUCT((COUNTIFS(Branches_Data!$A$2:$A$31,Customer_Data!$U$2:$U$1051,Branches_Data!$E$2:$E$31,"West")>0)*1)} -> 237
A51: Customer Status Breakdown
A52: CustomerStatus | B52: Count
...

Sheet Customer_Data
A1: CustomerID | B1: CustomerName | C1: DOB | D1: DOB_Valid | E1: Age | F1: Gender | G1: Phone | H1: Email | I1: Address | J1: City | K1: State | L1: PAN | M1: PAN_Valid | N1: Aadhaar | O1: Aadhaar_Valid | P1: Occupation | Q1: AnnualIncome | R1: AnnualIncome_Status | S1: AccountOpenDate | T1: AccountOpenDate_Valid | U1: BranchID | V1: CustomerStatus | W1: DuplicateFlag
A2: CUST00964 | B2: Sunil Kumar | C2: 29116 | D2: Yes | E2: 46 | F2: Male | G2: 9217640914 | H2: sunil.kumar964@gmail.com | I2: 178, Ring Road | J2: Gurugram | K2: Haryana | L2: VFXOR1378H | M2: Yes | O2: Missing | P2: Retired | Q2: 1137861 | R2: Disclosed | S2: 44548 | T2: Yes | U2: BR023 | V2: Active | W2: Unique
A3: CUST00065 | B3: Vivek Chowdhury | C3: 34273 | D3: Yes | E3: 32 | F3: Male | G3: 9461450066 | H3: vivek.chowdhury65@gmail.com | I3: 974, FC Road | J3: Ludhiana | K3: Punjab | L3: VOZBQ1888B | M3: Yes | N3: 429026424848 | O3: Yes | P3: Student | Q3: 1084986 | R3: Disclosed | S3: 41072 | T3: Yes | U3: BR025 | V3: Active | W3: Unique
A4: CUST00851 | B4: Sunil Desai | C4: 33788 | D4: Yes | E4: 34 | F4: Male | G4: 9704316147 | H4: sunil.desai851@gmail.com | I4: 150, Park Street | J4: Mumbai | K4: Maharashtra | L4: VEYVZ2679V | M4: Yes | N4: 058305047711 | O4: Yes | P4: Business Owner | Q4: 1184996 | R4: Disclosed | S4: 38932 | T4: Yes | U4: BR015 | V4: Active | W4: Unique
A5: CUST00642 | B5: Nidhi Mehta | C5: 35631 | D5: Yes | E5: 29 | F5: Female | G5: 9273612074 | H5: nidhi.mehta642@gmail.com | I5: 888, Park Street | J5: Surat | K5: Gujarat | L5: EPYFS7861X | M5: Yes | N5: 082561657221 | O5: Yes | P5: Government Employee | Q5: 162469 | R5: Disclosed | S5: 43520 | T5: Yes | U5: BR002 | V5: Active | W5: Unique
A6: CUST00827 | B6: Ritu Chopra | C6: 27687 | D6: Yes | E6: 50 | F6: Female | G6: 1847894038 | H6: ritu.chopra827@gmail.com | I6: 723, FC Road | J6: Thiruvananthapuram | K6: Kerala | L6: IIUMH3252G | M6: Yes | N6: 502565712390 | O6: Yes | P6: Business Owner | Q6: 1918084 | R6: Disclosed | S6: 42877 | T6: Yes | U6: BR025 | V6: Inactive | W6: Unique
A7: CUST00586 | B7: Siddharth Patel | C7: 31112 | D7: Yes | E7: 41 | F7: Male | G7: 9024334316 | H7: siddharth.patel586@gmail.com | I7: 909, MG Road | J7: Delhi | K7: Delhi | L7: VYUYL5923Z | M7: Yes | N7: 668455730970 | O7: Yes | P7: Government Employee | R7: Not Disclosed | S7: 42641 | T7: Yes | U7: BR029 | V7: Active | W7: Unique
A8: CUST00151 | B8: Seema Rane | C8: 29695 | D8: Yes | E8: 45 | F8: Female | G8: 9592476363 | H8: seema.rane151@gmail.com | I8: 59, FC Road | J8: Indore | K8: Madhya Pradesh | L8: GMTAG9670F | M8: Yes | O8: Missing | P8: Student | Q8: 162938 | R8: Disclosed | S8: 45603 | T8: Yes | U8: BR024 | V8: Active | W8: Unique
A9: CUST00517 | B9: Rekha Desai | C9: 31525 | D9: Yes | E9: 40 | F9: Female | G9: 9733385187 | H9: rekha.desai517@gmail.com | I9: 611, Ring Road | J9: Guwahati | K9: Assam | L9: DMVOR2092O | M9: Yes | N9: 784640036423 | O9: Yes | P9: Salaried | Q9: 1391390 | R9: Disclosed | S9: 41307 | T9: Yes | U9: BR001 | V9: Active | W9: Unique
A10: CUST00941 | B10: Shalini Menon | C10: 32696 | D10: Yes | E10: 37 | F10: Female | G10: 9756949781 | H10: shalini.menon941@gmail.com | I10: 449, FC Road | J10: Guwahati | K10: Assam | L10: YOCQC1314V | M10: Yes | N10: 005933312807 | O10: Yes | P10: Self-Employed | R10: Not Disclosed | S10: 39182 | T10: Yes | U10: BR009 | V10: Inactive | W10: Unique
A11: CUST00018 | B11: Vijay Gupta | C11: 27783 | D11: Yes | E11: 50 | F11: Male | G11: 9665072150 | H11: vijay.gupta18@yahoo.com | I11: 337, Park Street | J11: Ahmedabad | K11: Gujarat | L11: YKTEK0449A | M11: Yes | N11: 349806593311 | O11: Yes | P11: Salaried | R11: Not Disclosed | S11: 42778 | T11: Yes | U11: BR026 | V11: Active | W11: Unique
A12: CUST00161 | B12: Rajesh Patel | C12: 20353 | D12: Yes | E12: 70 | F12: Male | G12: 9004362345 | H12: rajesh.patel161@gmail.com | I12: 360, Nehru Nagar | J12: Gurugram | K12: Haryana | L12: DNGTW9281S | M12: Yes | N12: 875195621099 | O12: Yes | P12: Homemaker | R12: Not Disclosed | S12: 38687 | T12: Yes | U12: BR002 | V12: Active | W12: Possible Duplicate
A13: CUST00076 | B13: Nikhil Bose | C13: 36747 | D13: Yes | E13: 25 | F13: Male | G13: 9205521020 | H13: nikhil.bose76@gmail.com | I13: 601, Park Street | J13: Mysuru | K13: Karnataka | L13: EZACD9402C | M13: Yes | N13: 039657598642 | O13: Yes | P13: Unemployed | R13: Not Disclosed | S13: 44117 | T13: Yes | U13: BR030 | V13: Active | W13: Unique
A14: CUST00901 | B14: Radha Bose | C14: 38695 | D14: Yes | E14: 20 | F14: Female | G14: 9750078294 | H14: radha.bose901@yahoo.com | I14: 741, Park Street | J14: Bengaluru | K14: Karnataka | L14: FHITZ7917Y | M14: Yes | N14: 966386873908 | O14: Yes | P14: Government Employee | R14: Not Disclosed | S14: 40903 | T14: Yes | U14: BR010 | V14: Active | W14: Unique
A15: CUST01010 | B15: Neha Bhatt | C15: 36201 | D15: Yes | E15: 27 | F15: Female | G15: 9338146455 | H15: neha.bhatt121@gmail.com | I15: 898, Ring Road | J15: Ranchi | K15: Jharkhand | L15: VVSNJ6874A | M15: Yes | N15: 066714630159 | O15: Yes | P15: Government Employee | R15: Not Disclosed | S15: 38541 | T15: Yes | U15: BR021 | V15: Active | W15: Possible Duplicate
A16: CUST00749 | B16: Vandana Patel | C16: 36157 | D16: Yes | E16: 27 | F16: Female | G16: 9083970669 | H16: vandana.patel749@gmail.com | I16: 794, FC Road | J16: Chennai | K16: Tamil Nadu | L16: JOJSZ9543Q | M16: Yes | N16: 595707681757 | O16: Yes | P16: Government Employee | Q16: 760186 | R16: Disclosed | S16: 41179 | T16: Yes | U16: BR017 | V16: Active | W16: Unique
A17: CUST00158 | B17: Lata Bhatt | C17: 32855 | D17: Yes | E17: 36 | F17: Female | G17: 9926037860 | H17: lata.bhatt158@gmail.com | I17: 293, Church Street | J17: Mumbai | K17: Maharashtra | L17: WKPGR7615G | M17: Yes | N17: 963764443429 | O17: Yes | P17: Freelancer | Q17: 194856 | R17: Disclosed | S17: 43899 | T17: Yes | U17: BR030 | V17: Active | W17: Unique
A18: CUST00001 | B18: Aarti Verma | C18: 30166 | D18: Yes | E18: 44 | F18: Female | G18: 9767363842 | H18: aarti.verma1@gmail.com | I18: 8, MG Road | J18: Noida | K18: Uttar Pradesh | L18: TVZND6915P | M18: Yes | O18: Missing | P18: Salaried | Q18: 281755 | R18: Disclosed | S18: 38933 | T18: Yes | U18: BR008 | V18: Active | W18: Unique
A19: CUST00617 | B19: Pooja Kulkarni | C19: 27663 | D19: Yes | E19: 50 | F19: Female | G19: 9411727617 | H19: pooja.kulkarni617@gmail.com | I19: 25, Park Street | J19: Mumbai | K19: Maharashtra | L19: PYGGE5362C | M19: Yes | N19: 852429368734 | O19: Yes | P19: Government Employee | Q19: 1025219 | R19: Disclosed | S19: 45418 | T19: Yes | U19: BR016 | V19: Active | W19: Unique
A20: CUST00526 | B20: Naveen Kapoor | C20: 32032 | D20: Yes | E20: 38 | F20: Male | G20: 9590786917 | H20: naveen.kapoor526@gmail.com | I20: 938, Church Street | J20: Thiruvananthapuram | K20: Kerala | L20: LLPZC6797F | M20: Yes | N20: 774942760359 | O20: Yes | P20: Government Employee | R20: Not Disclosed | S20: 39417 | T20: Yes | U20: BR021 | V20: Active | W20: Unique
A21: CUST00661 | B21: Suresh Khanna | C21: 37098 | D21: Yes | E21: 25 | F21: Male | G21: 9161950768 | H21: suresh.khanna661@gmail.com | I21: 846, Park Street | J21: Mumbai | K21: Maharashtra | L21: QSHVT2595H | M21: Yes | N21: 253545120295 | O21: Yes | P21: Student | R21: Not Disclosed | S21: 44581 | T21: Yes | U21: BR008 | V21: Active | W21: Unique
A22: CUST00788 | B22: Rekha Verma | C22: 30591 | D22: Yes | E22: 42 | F22: Female | G22: 9716075746 | H22: rekha.verma788@gmail.com | I22: 842, Church Street | J22: Hyderabad | K22: Telangana | L22: YWVXU0402N | M22: Yes | N22: 068421482647 | O22: Yes | P22: Business Owner | R22: Not Disclosed | S22: 45665 | T22: Yes | U22: BR022 | V22: Active | W22: Unique
A23: CUST00598 | B23: Girish Desai | C23: 34042 | D23: Yes | E23: 33 | F23: Male | G23: 9544111561 | H23: girish.desai598@yahoo.com | I23: 820, Park Street | J23: Lucknow | K23: Uttar Pradesh | L23: OZOFG0625O | M23: Yes | N23: 065577328160 | O23: Yes | P23: Business Owner | Q23: 496885 | R23: Disclosed | S23: 43635 | T23: Yes | U23: BR017 | V23: Active | W23: Unique
A24: CUST00075 | B24: Manoj Bansal | C24: 34229 | D24: Yes | E24: 32 | F24: Male | G24: 9145255693 | H24: manoj.bansal75@gmail.com | I24: 569, Ring Road | J24: Thiruvananthapuram | K24: Kerala | L24: UUJPT7601M | M24: Yes | N24: 905520705532 | O24: Yes | P24: Retired | Q24: 1594335 | R24: Disclosed | S24: 44380 | T24: Yes | U24: BR028 | V24: Active | W24: Unique
A25: CUST00462 | B25: Asha Agarwal | C25: 24735 | D25: Yes | E25: 58 | F25: Female | G25: 9578072679 | H25: asha.agarwal462@gmail.com | I25: 391, Park Street | J25: Kanpur | K25: Uttar Pradesh | L25: LCLTV6657W | M25: Yes | N25: 231773759344 | O25: Yes | P25: Freelancer | R25: Not Disclosed | S25: 40784 | T25: Yes | U25: BR003 | V25: Active | W25: Unique
A26: CUST00540 | B26: Swati Nair | C26: 22124 | D26: Yes | E26: 66 | F26: Female | G26: 9810505195 | H26: swati.nair540@gmail.com | I26: 306, FC Road | J26: Coimbatore | K26: Tamil Nadu | L26: NWZCA749 | M26: No | N26: 918674561283 | O26: Yes | P26: Unemployed | Q26: 1833341 | R26: Disclosed | S26: 40250 | T26: Yes | U26: BR014 | V26: Active | W26: Unique
A27: CUST00380 | B27: Gaurav Bhatt | C27: 27714 | D27: Yes | E27: 50 | F27: Male | G27: 9947869211 | H27: gaurav.bhatt380@gmail.com | I27: 230, MG Road | J27: Lucknow | K27: Uttar Pradesh | L27: FWEAE4955C | M27: Yes | N27: 926280584879 | O27: Yes | P27: Freelancer | Q27: 1318688 | R27: Disclosed | S27: 41902 | T27: Yes | U27: BR030 | V27: Inactive | W27: Unique
A28: CUST00796 | B28: Lata Sharma | C28: 34155 | D28: Yes | E28: 33 | F28: Female | H28: lata.sharma796@yahoo.com | I28: 998, Park Street | J28: Ludhiana | K28: Punjab | M28: Missing | N28: 038096791047 | O28: Yes | P28: Student | R28: Not Disclosed | S28: 45988 | T28: Yes | U28: BR016 | V28: Active | W28: Unique
A29: CUST00913 | B29: Rajesh Sharma | C29: 28713 | D29: Yes | E29: 47 | F29: Male | G29: 9214389826 | H29: rajesh.sharma913@gmail.com | I29: 51, Ring Road | J29: Kolkata | K29: West Bengal | L29: FKUTE4684K | M29: Yes | N29: 854579900356 | O29: Yes | P29: Freelancer | R29: Not Disclosed | S29: 44899 | T29: Yes | U29: BR029 | V29: Inactive | W29: Unique
A30: CUST00143 | B30: Aditya Khanna | C30: 35209 | D30: Yes | E30: 30 | F30: Male | G30: 9795339034 | H30: aditya.khanna143@gmail.com | I30: 567, Park Street | J30: Thiruvananthapuram | K30: Kerala | L30: KLWAD8374R | M30: Yes | N30: 324776255019 | O30: Yes | P30: Salaried | R30: Not Disclosed | S30: 39882 | T30: Yes | U30: BR003 | V30: Active | W30: Unique
A31: CUST00402 | B31: Sneha Mehta | C31: 33304 | D31: Yes | E31: 35 | F31: Female | G31: 9284348137 | H31: sneha.mehta402@gmail.com | I31: 768, Ring Road | J31: Nashik | K31: Maharashtra | L31: AFXRM9324S | M31: Yes | N31: 786616140306 | O31: Yes | P31: Self-Employed | R31: Not Disclosed | S31: 39415 | T31: Yes | U31: BR016 | V31: Active | W31: Unique
A32: CUST00713 | B32: Sarita Nair | C32: 34432 | D32: Yes | E32: 32 | F32: Female | G32: 9691951904 | H32: sarita.nair713@yahoo.com | I32: 433, Church Street | J32: Kochi | K32: Kerala | L32: KHHRH6901W | M32: Yes | O32: Missing | P32: Retired | Q32: 1090848 | R32: Disclosed | S32: 39154 | T32: Yes | U32: BR020 | V32: Inactive | W32: Unique
A33: CUST00859 | B33: Aatri Agarwal | C33: 32005 | D33: Yes | E33: 38 | F33: Female | G33: 9605617112 | H33: aarti.agarwal859@yahoo.com | I33: 881, FC Road | J33: Bhopal | K33: Madhya Pradesh | L33: GVLHG8922W | M33: Yes | N33: 133345022360 | O33: Yes | P33: Government Employee | Q33: 2397230 | R33: Disclosed | S33: 43412 | T33: Yes | U33: BR004 | V33: Active | W33: Unique
A34: CUST00696 | B34: Meera Nair | C34: 21902 | D34: Yes | E34: 66 | F34: Female | G34: 9184094587 | I34: 512, Nehru Nagar | J34: Coimbatore | K34: Tamil Nadu | L34: FSPMY8603V | M34: Yes | N34: 571404466581 | O34: Yes | P34: Freelancer | Q34: 1516937 | R34: Disclosed | S34: 38444 | T34: Yes | U34: BR022 | V34: Inactive | W34: Unique
A35: CUST00433 | B35: Rekha Joshi | C35: 20310 | D35: Yes | E35: 70 | F35: Female | G35: 9447651669 | H35: rekha.joshi433@gmail.com | I35: 935, Church Street | J35: Surat | K35: Gujarat | L35: YOBTN0900X | M35: Yes | N35: 128920377599 | O35: Yes | P35: Salaried | Q35: 1103551 | R35: Disclosed | S35: 42926 | T35: Yes | U35: BR025 | V35: Active | W35: Unique
A36: CUST00597 | B36: Payal Yadav | C36: 23762 | D36: Yes | E36: 61 | F36: Female | G36: 9172494639 | H36: payal.yadav597@gmail.com | I36: 382, Ring Road | J36: Guwahati | K36: Assam | L36: VZJGY8967S | M36: Yes | N36: 763034787443 | O36: Yes | P36: Freelancer | Q36: 894253 | R36: Disclosed | S36: 39537 | T36: Yes | U36: BR027 | V36: Inactive | W36: Unique
A37: CUST01014 | B37: Namrata Shah | C37: 24054 | D37: Yes | E37: 60 | F37: Female | G37: 9214309733 | H37: namrata.shah784@gmail.com | I37: 81, FC Road | J37: Jaipur | K37: Rajasthan | M37: Missing | N37: 695669295354 | O37: Yes | P37: Self-Employed | Q37: 1153905 | R37: Disclosed | S37: 43137 | T37: Yes | U37: BR024 | V37: Active | W37: Possible Duplicate
A38: CUST00175 | B38: Varun Iyer | C38: 28617 | D38: Yes | E38: 48 | F38: Male | G38: 9716218783 | H38: varun.iyer175@gmail.com | I38: 24, Nehru Nagar | J38: Guwahati | K38: Assam | L38: AAUDQ5950T | M38: Yes | O38: Missing | P38: Self-Employed | R38: Not Disclosed | S38: 39514 | T38: Yes | U38: BR009 | V38: Active | W38: Unique
A39: CUST00679 | B39: Ritu Mehta | C39: 34625 | D39: Yes | E39: 31 | F39: Female | G39: 9541955824 | H39: ritu.mehta679@gmail.com | I39: 90, Ring Road | J39: Lucknow | K39: Uttar Pradesh | L39: IJKIA0769A | M39: Yes | N39: 919034721195 | O39: Yes | P39: Freelancer | R39: Not Disclosed | S39: 45447 | T39: Yes | U39: BR007 | V39: Active | W39: Unique
A40: CUST01034 | B40: Yogesh Singh | C40: 33334 | D40: Yes | E40: 35 | F40: Male | G40: 9007560427 | H40: yogesh.singh14@yahoo.com | I40: 425, FC Road | J40: Gurugram | K40: Haryana | L40: BNQML021 | M40: No | N40: 196215509941 | O40: Yes | P40: Unemployed | Q40: 160759 | R40: Disclosed | S40: 44300 | T40: Yes | U40: BR027 | V40: Active | W40: Possible Duplicate
...

Sheet Branches_Data
A1: BranchID | B1: BranchName | C1: City | D1: State | E1: Region | F1: Manager | G1: OpeningDate
A2: BR001 | B2: Indore City Center Branch | C2: Indore | D2: Madhya Pradesh | E2: Central | F2: Ritu Kapoor | G2: 40348
A3: BR002 | B3: Nashik City Center Branch | C3: Nashik | D3: Maharashtra | E3: West | F3: Mahesh Kapoor | G3: 37470
A4: BR003 | B4: Pune Main Branch | C4: Pune | D4: Maharashtra | E4: West | F4: Swati Reddy | G4: 41677
A5: BR004 | B5: Kochi Camp Branch | C5: Kochi | D5: Kerala | E5: South | F5: Nidhi Agarwal | G5: 36507
A6: BR005 | B6: Hyderabad Mg Road Branch | C6: Hyderabad | D6: Telangana | E6: South | F6: Seema Iyer | G6: 41997
A7: BR006 | B7: Coimbatore Main Branch | C7: Coimbatore | D7: Tamil Nadu | E7: South | F7: Namrata Pillai | G7: 41721
A8: BR007 | B8: Chandigarh Station Road Branch | C8: Chandigarh | D8: Punjab | E8: North | F8: Sandeep Kumar | G8: 36546
A9: BR008 | B9: Bengaluru City Center Branch | C9: Bengaluru | D9: Karnataka | E9: South | F9: Anand Singh | G9: 39610
A10: BR009 | B10: Guwahati Main Branch | C10: Guwahati | D10: Assam | E10: East | F10: Swati Bhatt | G10: 43224
A11: BR010 | B11: Kolkata Camp Branch | C11: Kolkata | D11: West Bengal | E11: East | F11: Arun Yadav | G11: 41616
A12: BR011 | B12: Nagpur City Center Branch | C12: Nagpur | D12: Maharashtra | E12: West | F12: Rakesh Kumar | G12: 38599
A13: BR012 | B13: Kanpur Station Road Branch | C13: Kanpur | D13: Uttar Pradesh | E13: North | F13: Siddharth Joshi | G13: 43369
... A31: BR030 | B31: Thiruvananthapuram Camp Branch | C31: Thiruvananthapuram | D31: Kerala | E31: South | F31: Arun Bansal | G31: 35805

Sheet KYC_Data
A1: KYCID | B1: CustomerID | C1: PAN | D1: Aadhaar | E1: KYCStatus | F1: KYCDate | G1: DocumentType
A2: KYC00001 | B2: CUST00491 | C2: IYRGS8977D | D2: 573918697126 | E2: Rejected | F2: 44251 | G2: Voter Id
A3: KYC00002 | B3: CUST00983 | C3: EYIBM4748X | D3: 682553426009 | E3: Verified | F3: 42564 | G3: Aadhaar Card
A4: KYC00003 | B4: CUST00329 | C4: CZGUR9795I | D4: 615580795606 | E4: Verified | F4: 44197 | G4: Passport
A5: KYC00004 | B5: CUST00878 | C5: LPCDW5581T | D5: 926103583850 | E5: Rejected | F5: 40993 | G5: Pan Card
A6: KYC00005 | B6: CUST00749 | C6: JOJSZ9543Q | D6: 595707681757 | E6: Verified | F6: 42619 | G6: Aadhaar Card
A7: KYC00006 | B7: CUST00723 | C7: NLEKH8512L | D7: 340104309161 | E7: Pending | G7: Driving Licence
A8: KYC00007 | B8: CUST00393 | D8: 555890111956 | E8: Verified | F8: 42467 | G8: Driving Licence
A9: KYC00008 | B9: CUST00942 | C9: LSUVY1419G | D9: 552323582789 | E9: Verified | F9: 45799 | G9: Aadhaar Card
A10: KYC00009 | B10: CUST00348 | C10: AQIEG5279O | D10: 148177045487 | E10: Verified | F10: 44967 | G10: Passport
A11: KYC00010 | B11: CUST00031 | D11: 234005323458 | E11: Verified | F11: 45089 | G11: Passport
A12: KYC00011 | B12: CUST00014 | C12: BNQML021 | D12: 196215509941 | E12: Verified | F12: 46001 | G12: Voter Id
A13: KYC00012 | B13: CUST00722 | C13: LHEZG9699X | D13: 964725113437 | E13: Verified | F13: 41040 | G13: Passport
A14: KYC00013 | B14: CUST01044 | C14: NSNLZ2093V | E14: Verified | F14: 43593 | G14: Voter Id
A15: KYC00014 | B15: CUST00530 | C15: OGRCQ4778I | D15: 449119666324 | E15: Verified | F15: 40843 | G15: Driving Licence
A16: KYC00015 | B16: CUST00627 | C16: PGUCG1515X | D16: 200985642534 | E16: Verified | F16: 45443 | G16: Voter Id
A17: KYC00016 | B17: CUST00002 | C17: RJKWB6607U | E17: Verified | F17: 40682 | G17: Aadhaar Card
A18: KYC00017 | B18: CUST00625 | C18: CTNMK7616D | E18: Verified | F18: 44956 | G18: Voter Id
A19: KYC00018 | B19: CUST00897 | C19: NWZFD7024S | D19: 358944626321 | E19: Verified | F19: 41971 | G19: Aadhaar Card
A20: KYC00019 | B20: CUST00248 | C20: IZPEM5298G | D20: 688689933510 | E20: Verified | F20: 45328 | G20: Voter Id
A21: KYC00020 | B21: CUST00832 | C21: UBPZG8734N | D21: 786960748891 | E21: Rejected | F21: 45009 | G21: Pan Card
A22: KYC00021 | B22: CUST00120 | C22: KWBNS1542H | D22: 714336907709 | E22: Verified | F22: 44164 | G22: Aadhaar Card
A23: KYC00022 | B23: CUST00217 | C23: QCTEA8541T | D23: 608368112337 | E23: Verified | F23: 42473 | G23: Aadhaar Card
A24: KYC00023 | B24: CUST00498 | C24: JDPER0599H | D24: 119272522047 | E24: Pending | G24: Voter Id
A25: KYC00024 | B25: CUST00918 | C25: MVGZV4172L | D25: 808168304331 | E25: Verified | F25: 43351 | G25: Voter Id
A26: KYC00025 | B26: CUST00143 | C26: KLWAD8374R | D26: 324776255019 | E26: Verified | F26: 45969 | G26: Aadhaar Card
A27: KYC00026 | B27: CUST00575 | C27: OJOBV3490I | D27: 790552441266 | E27: Verified | F27: 41410 | G27: Aadhaar Card
A28: KYC00027 | B28: CUST00671 | C28: ETTTA2042C | D28: 568503097268 | E28: Verified | F28: 45573 | G28: Voter Id
A29: KYC00028 | B29: CUST00711 | C29: JCIDS8668S | D29: 633159578581 | E29: Verified | F29: 40495 | G29: Driving Licence
A30: KYC00029 | B30: CUST00609 | C30: RZHQR2731B | D30: 388230611337 | E30: Verified | F30: 41595 | G30: Aadhaar Card
A31: KYC00030 | B31: CUST00993 | C31: LGZDC8690L | D31: 633422184326 | E31: Verified | F31: 44730 | G31: Pan Card
A32: KYC00031 | B32: CUST00566 | C32: XBUFU8346N | D32: 681053178020 | E32: Verified | F32: 44198 | G32: Passport
A33: KYC00032 | B33: CUST00620 | C33: PTHEP6340G | D33: 036767913701 | E33: Pending | G33: Aadhaar Card
A34: KYC00033 | B34: CUST00401 | D34: 285507407649 | E34: Verified | F34: 40787 | G34: Driving Licence
A35: KYC00034 | B35: CUST00406 | C35: OKYJM7996W | D35: 802881103428 | E35: Rejected | F35: 44718 | G35: Voter Id
A36: KYC00035 | B36: CUST00619 | C36: NYOUZ9380X | D36: 410155040890 | E36: Verified | F36: 45444 | G36: Driving Licence
A37: KYC00036 | B37: CUST00112 | C37: TMZPJ4426Z | E37: Verified | F37: 41980 | G37: Pan Card
A38: KYC00037 | B38: CUST00290 | C38: JRCKW3754C | D38: 257571915979 | E38: Pending | G38: Passport
A39: KYC00038 | B39: CUST00110 | C39: ZNDAY7991Z | D39: 556289796779 | E39: Pending | G39: Driving Licence
A40: KYC00039 | B40: CUST00466 | C40: HVSEO8689V | D40: 888917118152 | E40: Verified | F40: 42627 | G40: Voter Id
...

Sheet Loan_Data
A1: LoanID | B1: CustomerID | C1: LoanType | D1: LoanAmount | E1: InterestRate | F1: TenureMonths | G1: SanctionDate | H1: LoanStatus | I1: OutstandingAmount | J1: BranchID | K1: OutstandingAmount_Status
A2: LN00001 | B2: CUST00206 | C2: Gold Loan | D2: 139928 | E2: 8.37 | F2: 24 | G2: 44333 | H2: Closed | I2: 0 | J2: BR006 | K2: OK
A3: LN00002 | B3: CUST00307 | C3: Auto Loan | D3: 488294 | E3: 8.52 | F3: 12 | G3: 42420 | H3: Closed | I3: 0 | J3: BR008 | K3: OK
A4: LN00003 | B4: CUST00233 | C4: Home Loan | D4: 8997711 | E4: 13.22 | F4: 120 | G4: 44461 | H4: Active | I4: 6795003.2 | J4: BR005 | K4: OK
A5: LN00004 | B5: CUST00402 | C5: Personal Loan | D5: 842321 | E5: 7.76 | F5: 180 | G5: 45448 | H5: Closed | I5: 0 | J5: BR029 | K5: OK
A6: LN00005 | B6: CUST00747 | C6: Gold Loan | D6: 220874 | E6: 10.96 | F6: 12 | G6: 41008 | H6: Closed | I6: 0 | J6: BR030 | K6: OK
A7: LN00006 | B7: CUST00419 | C7: Auto Loan | D7: 325647 | E7: 12.36 | F7: 24 | G7: 41691 | H7: Active | I7: 52167.34 | J7: BR023 | K7: OK
A8: LN00007 | B8: CUST00261 | C8: Gold Loan | D8: 41340 | E8: 9.32 | F8: 84 | G8: 41075 | H8: Active | I8: 19204.15 | J8: BR027 | K8: OK
A9: LN00008 | B9: CUST00201 | C9: Personal Loan | D9: 286056 | E9: 8.48 | F9: 180 | G9: 43291 | H9: Active | I9: 232282.13 | J9: BR010 | K9: OK
A10: LN00009 | B10: CUST00828 | C10: Gold Loan | D10: 61378 | E10: 8.74 | F10: 24 | G10: 45432 | H10: Active | I10: 40436.45 | J10: BR027 | K10: OK
A11: LN00010 | B11: CUST00211 | C11: Education Loan | D11: 787746 | E11: 14.59 | F11: 180 | G11: 42437 | H11: Active | I11: 387221.85 | J11: BR030 | K11: OK
A12: LN00011 | B12: CUST00252 | C12: Education Loan | D12: 1684206 | E12: 7.96 | F12: 240 | G12: 43152 | H12: Closed | I12: 0 | J12: BR029 | K12: OK
A13: LN00012 | B13: CUST00060 | C13: Home Loan | D13: 6696819 | E13: 12.85 | F13: 60 | G13: 42387 | H13: Closed | I13: 0 | J13: BR027 | K13: OK
... A158: LN00157 | B158: CUST00681 | C158: Gold Loan | D158: 435932 | E158: 9.93 | F158: 60 | G158: 41009 | H158: Active | I158: 46872.8 | J158: BR006 | K158: OK
A159: LN00158 | B159: CUST01048 | C159: Personal Loan | D159: 387359 | E159: 10.83 | F159: 60 | G159: 42501 | H159: Active | J159: BR011 | K159: Needs Review
A160: LN00159 | B160: CUST00050 | C160: Education Loan | D160: 1819930 | E160: 10.92 | F160: 12 | G160: 44389 | H160: Closed | I160: 0 | J160: BR015 | K160: OK
A161: LN00160 | B161: CUST00437 | C161: Personal Loan | D161: 749328 | E161: 10.29 | F161: 180 | G161: 43940 | H161: Default | I161: 632282.04 | J161: BR022 | K161: OK
A162: LN00161 | B162: CUST00554 | C162: Home Loan | D162: 5446137 | E162: 7.87 | F162: 180 | G162: 45608 | H162: Active | I162: 2813663.9 | J162: BR008 | K162: OK
A163: LN00162 | B163: CUST00822 | C163: Gold Loan | D163: 165624 | E163: 11.16 | F163: 24 | G163: 44946 | H163: Active | I163: 100302.86 | J163: BR021 | K163: OK
A164: LN00163 | B164: CUST00623 | C164: Education Loan | D164: 139611 | E164: 15.1 | F164: 24 | G164: 41050 | H164: Default | I164: 117635.3 | J164: BR007 | K164: OK
A165: LN00164 | B165: CUST00752 | C165: Home Loan | D165: 3412644 | E165: 16.48 | F165: 60 | G165: 44523 | H165: Active | I165: 120626.56 | J165: BR002 | K165: OK
A166: LN00165 | B166: CUST00321 | C166: Personal Loan | D166: 80040 | E166: 14.07 | F166: 120 | G166: 42103 | H166: Active | I166: 53726.33 | J166: BR029 | K166: OK
A167: LN00166 | B167: CUST00846 | C167: Business Loan | D167: 943891 | E167: 12.76 | F167: 60 | G167: 45482 | H167: Active | I167: 61979 | J167: BR026 | K167: OK
A168: LN00167 | B168: CUST00608 | C168: Personal Loan | D168: 445804 | E168: 10.98 | F168: 84 | G168: 42587 | H168: Active | I168: 375801.88 | J168: BR024 | K168: OK
A169: LN00168 | B169: CUST00023 | C169: Education Loan | D169: 535655 | E169: 7.63 | F169: 240 | G169: 42619 | H169: Closed | I169: 0 | J169: BR026 | K169: OK
A170: LN00169 | B170: CUST00505 | C170: Education Loan | D170: 1880479 | E170: 12.22 | F170: 12 | G170: 43707 | H170: Active | I170: 1442539.1 | J170: BR001 | K170: OK
A171: LN00170 | B171: CUST00660 | C171: Auto Loan | D171: 906866 | E171: 13.2 | F171: 120 | G171: 42893 | H171: Active | I171: 440199.94 | J171: BR006 | K171: OK
... A206: LN00205 | B206: CUST00074 | C206: Education Loan | D206: 974429 | E206: 7.99 | F206: 24 | G206: 42590 | H206: Active | I206: 693067.15 | J206: BR006 | K206: OK
A207: LN00206 | B207: CUST00158 | C207: Personal Loan | D207: 884808 | E207: 14.01 | F207: 24 | G207: 42850 | H207: Active | J207: BR003 | K207: Needs Review
A208: LN00207 | B208: CUST00672 | C208: Personal Loan | D208: 768703 | E208: 11.13 | F208: 36 | G208: 42194 | H208: Active | I208: 406793.03 | J208: BR002 | K208: OK
A209: LN00208 | B209: CUST00992 | C209: Home Loan | D209: 3447034 | E209: 9.56 | F209: 180 | G209: 44999 | H209: Closed | I209: 0 | J209: BR017 | K209: OK
A210: LN00209 | B210: CUST00877 | C210: Education Loan | D210: 270002 | E210: 9.23 | F210: 120 | G210: 44109 | H210: Active | I210: 143342.42 | J210: BR030 | K210: OK
A211: LN00210 | B211: CUST00176 | C211: Business Loan | D211: 4476442 | E211: 12.22 | F211: 240 | G211: 43218 | H211: NPA | I211: 2108135.1 | J211: BR010 | K211: OK
A212: LN00211 | B212: CUST00003 | C212: Auto Loan | D212: 461232 | E212: 12.61 | F212: 60 | G212: 42683 | H212: Active | I212: 327151.09 | J212: BR005 | K212: OK
A213: LN00212 | B213: CUST00286 | C213: Business Loan | D213: 1835864 | E213: 10.26 | F213: 120 | G213: 44656 | H213: Closed | I213: 0 | J213: BR016 | K213: OK
A214: LN00213 | B214: CUST00834 | C214: Home Loan | D214: 4624356 | E214: 11.88 | F214: 84 | G214: 43657 | H214: Closed | I214: 0 | J214: BR010 | K214: OK
A215: LN00214 | B215: CUST00301 | C215: Home Loan | D215: 3189929 | E215: 12.75 | F215: 84 | G215: 42204 | H215: Closed | I215: 0 | J215: BR004 | K215: OK
A216: LN00215 | B216: CUST00789 | C216: Home Loan | D216: 7288631 | E216: 14.26 | F216: 240 | G216: 44414 | H216: Active | I216: 4851898.8 | J216: BR001 | K216: OK
A217: LN00216 | B217: CUST00491 | C217: Auto Loan | D217: 857244 | E217: 11.97 | F217: 36 | G217: 43218 | H217: Active | I217: 285257.9 | J217: BR007 | K217: OK
A218: LN00217 | B218: CUST00339 | C218: Personal Loan | D218: 940216 | E218: 9.97 | F218: 84 | G218: 43003 | H218: Active | I218: 803339.43 | J218: BR006 | K218: OK
...

Sheet Creditcard_Data
A1: CardID | B1: CustomerID | C1: CardType | D1: CardLimit | E1: CurrentOutstanding | F1: IssueDate | G1: CardStatus | H1: LastPaymentDate | I1: LastPaymentDate_Status
A2: CC00001 | B2: CUST01006 | C2: Business | D2: 800000 | E2: 678824.1 | F2: 44125 | G2: Active | H2: 46270 | I2: OK
A3: CC00002 | B3: CUST00118 | C3: Signature | D3: 500000 | E3: 183158.54 | F3: 43565 | G3: Active | H3: 46237 | I3: OK
A4: CC00003 | B4: CUST00980 | C4: Business | D4: 800000 | E4: 399830.68 | F4: 43555 | G4: Closed | H4: 45994 | I4: OK
A5: CC00004 | B5: CUST00538 | C5: Classic | D5: 75000 | E5: 4050.2 | F5: 44666 | G5: Closed | H5: 45270 | I5: OK
A6: CC00005 | B6: CUST00714 | C6: Platinum | D6: 300000 | E6: 38955.28 | F6: 42604 | G6: Active | H6: 45417 | I6: OK
A7: CC00006 | B7: CUST00717 | C7: Business | D7: 800000 | E7: 704451.14 | F7: 43956 | G7: Active | H7: 46351 | I7: OK
A8: CC00007 | B8: CUST00519 | C8: Gold | D8: 150000 | E8: 54560.71 | F8: 42625 | G8: Active | H8: 46287 | I8: OK
A9: CC00008 | B9: CUST00945 | C9: Gold | D9: 150000 | E9: 69598.05 | F9: 42219 | G9: Closed | H9: 45860 | I9: OK
A10: CC00009 | B10: CUST00410 | C10: Signature | D10: 500000 | E10: 76247.69 | F10: 45814 | G10: Closed | I10: No Payment Recorded
A11: CC00010 | B11: CUST00388 | C11: Signature | D11: 500000 | E11: 383103.19 | F11: 45545 | G11: Active | H11: 45119 | I11: OK
A12: CC00011 | B12: CUST00687 | C12: Business | D12: 800000 | E12: 595147.97 | F12: 45266 | G12: Active | H12: 46366 | I12: OK
A13: CC00012 | B13: CUST00482 | C13: Signature | D13: 500000 | E13: 340228.21 | F13: 44973 | G13: Active | H13: 45324 | I13: OK
A14: CC00013 | B14: CUST00191 | C14: Signature | D14: 500000 | E14: 363924.91 | F14: 44855 | G14: Active | H14: 45024 | I14: OK
A15: CC00014 | B15: CUST00588 | C15: Business | D15: 800000 | E15: 832721.87 | F15: 42493 | G15: Active | I15: No Payment Recorded
A16: CC00015 | B16: CUST00595 | C16: Gold | D16: 150000 | E16: 3557.02 | F16: 45514 | G16: Active | H16: 45159 | I16: OK
A17: CC00016 | B17: CUST00650 | C17: Gold | D17: 150000 | E17: 150335.64 | F17: 44744 | G17: Active | H17: 45383 | I17: OK
A18: CC00017 | B18: CUST00134 | C18: Business | D18: 800000 | E18: 107698.93 | F18: 42922 | G18: Active | H18: 44959 | I18: OK
A19: CC00018 | B19: CUST00662 | C19: Platinum | D19: 300000 | E19: 169799.46 | F19: 43224 | G19: Active | H19: 45438 | I19: OK
A20: CC00019 | B20: CUST00230 | C20: Signature | D20: 500000 | E20: 409976.61 | F20: 42574 | G20: Blocked | H20: 46141 | I20: OK
A21: CC00020 | B21: CUST00160 | C21: Signature | D21: 500000 | E21: 430225.27 | F21: 45562 | G21: Active | H21: 46282 | I21: OK
A22: CC00021 | B22: CUST00522 | C22: Signature | D22: 500000 | E22: 106926.38 | F22: 44576 | G22: Active | I22: No Payment Recorded
A23: CC00022 | B23: CUST00691 | C23: Gold | D23: 150000 | E23: 83119.14 | F23: 42043 | G23: Closed | H23: 46242 | I23: OK
A24: CC00023 | B24: CUST00042 | C24: Classic | D24: 75000 | E24: 49797.72 | F24: 44873 | G24: Blocked | I24: No Payment Recorded
A25: CC00024 | B25: CUST00934 | C25: Gold | D25: 150000 | E25: 11233.8 | F25: 44746 | G25: Active | H25: 45436 | I25: OK
A26: CC00025 | B26: CUST00389 | C26: Classic | D26: 75000 | E26: 12601.81 | F26: 42831 | G26: Active | I26: No Payment Recorded
A27: CC00026 | B27: CUST00962 | C27: Business | D27: 800000 | E27: 215814.43 | F27: 43150 | G27: Closed | H27: 45646 | I27: OK
A28: CC00027 | B28: CUST00165 | C28: Platinum | D28: 300000 | E28: 49696.64 | F28: 44795 | G28: Active | H28: 45826 | I28: OK
A29: CC00028 | B29: CUST00085 | C29: Platinum | D29: 300000 | E29: 6632.43 | F29: 45651 | G29: Active | H29: 45082 | I29: OK
A30: CC00029 | B30: CUST00088 | C30: Gold | D30: 150000 | E30: 20946.51 | F30: 42906 | G30: Active | H30: 46368 | I30: OK
A31: CC00030 | B31: CUST01039 | C31: Business | D31: 800000 | E31: 13567.84 | F31: 42987 | G31: Active | H31: 45566 | I31: OK
A32: CC00031 | B32: CUST00795 | C32: Gold | D32: 150000 | E32: 95071.03 | F32: 43352 | G32: Active | H32: 45613 | I32: OK
A33: CC00032 | B33: CUST00950 | C33: Gold | D33: 150000 | E33: 132195.15 | F33: 44840 | G33: Closed | H33: 45794 | I33: OK
A34: CC00033 | B34: CUST00173 | C34: Classic | D34: 75000 | E34: 64858.15 | F34: 42719 | G34: Active | I34: No Payment Recorded
A35: CC00034 | B35: CUST00464 | C35: Platinum | D35: 300000 | E35: 205420.44 | F35: 42914 | G35: Active | H35: 46157 | I35: OK
A36: CC00035 | B36: CUST00928 | C36: Gold | D36: 150000 | E36: 137597.04 | F36: 45137 | G36: Active | H36: 46105 | I36: OK
A37: CC00036 | B37: CUST00028 | C37: Classic | D37: 75000 | E37: 51384.62 | F37: 43346 | G37: Blocked | H37: 45007 | I37: OK
A38: CC00037 | B38: CUST00302 | C38: Classic | D38: 75000 | E38: 30234.67 | F38: 42597 | G38: Active | H38: 45936 | I38: OK
A39: CC00038 | B39: CUST00115 | C39: Signature | D39: 500000 | E39: 72820.43 | F39: 42741 | G39: Active | H39: 45006 | I39: OK
A40: CC00039 | B40: CUST01012 | C40: Business | D40: 800000 | E40: 459034.51 | F40: 44037 | G40: Active | H40: 45620 | I40: OK
...

Sheet Data_Quality_Log
A1: Sheet | B1: Column | C1: Issue Found | D1: Rows Affected | E1: Action Taken
A2: Customer_Data | B2: Gender | C2: Inconsistent casing/abbreviations (M/F/male/MALE etc.) | D2: 818 | E2: Standardized to Male / Female
A3: Customer_Data | B3: Phone | C3: 30 missing values; some had +91/dash prefixes | D3: 30 | E3: Stripped to 10-digit numeric string; missing left blank and flagged
A4: Customer_Data | B4: Email | C4: 57 missing values | D4: 57 | E4: Lower-cased; missing left blank and flagged
A5: Customer_Data | B5: PAN | C5: 98 missing, 18 not matching PAN format (stray spaces/chars) | D5: 116 | E5: Removed embedded spaces, upper-cased; added PAN_Valid flag column
A6: Customer_Data | B6: Aadhaar | C6: 100 missing, 18 not 12 digits | D6: 118 | E6: Removed non-digit characters; added Aadhaar_Valid flag column
A7: Customer_Data | B7: AnnualIncome | C7: 511 missing (49% of records) | D7: 511 | E7: Left blank (not imputed, to avoid biasing income analysis); flagged via AnnualIncome_Status
A8: Customer_Data | B8: DOB / AccountOpenDate | C8: Dates stored in 4+ mixed formats (DD-MM-YYYY, DD Mon YYYY, MM/DD/YYYY, YYYY-MM-DD) | D8: 1050 | E8: Parsed and standardized to a single date type (YYYY-MM-DD)
A9: Customer_Data | B9: DOB | C9: 41 records have a Date of Birth in the future | D9: 41 | E9: Flagged via DOB_Valid column; Age left blank for these records rather than showing a negative value
A10: Customer_Data | B10: AccountOpenDate | C10: 43 records have an account opening date earlier than the customer's DOB | D10: 43 | E10: Flagged via AccountOpenDate_Valid column for manual review
A11: Customer_Data | B11: CustomerName+DOB | C11: 100 records share the same name & date of birth (possible duplicate customer entries) | D11: 100 | E11: Flagged via DuplicateFlag column for manual review; not auto-deleted since CustomerIDs differ
A12: Customer_Data | B12: All rows | C12: Exact duplicate rows check | D12: 0 | E12: No exact duplicate rows found
A13: Branches_Data | B13: OpeningDate | C13: Date formatting standardized | D13: 30 | E13: Parsed to YYYY-MM-DD
... A19: Creditcard_Data | B19: IssueDate | C19: Mixed date formats | D19: 500 | E19: Standardized to YYYY-MM-DD
